<robot name="simple">
  <link name="Part4-2">
    <inertial>
      <origin xyz="0.02160620121324606 -0.10958533980702516 0.02597966333907257" rpy="0 0 0"/>
      <mass value="0.00204302"/>
      <inertia ixx="8.60805e-09" ixy="0.0" ixz="0.0" iyy="2.22351e-06" iyz="0.0" izz="2.22905e-06"/>
    </inertial>
    <visual>
      <origin xyz="0.07660586036889852 -0.10958518755115226 0.02447965538543597" rpy="0 0 0"/>
      <geometry>
        <mesh filename="simple - part4-2.stl"/>
      </geometry>
      <material name="Part4-2_color">
        <color rgba="0.792157 0.819608 0.933333 1.0"/>
      </material>
    </visual>
    <collision>
      <origin xyz="0.07660586036889852 -0.10958518755115226 0.02447965538543597" rpy="0 0 0"/>
      <geometry>
        <mesh filename="simple - part4-2.stl"/>
      </geometry>
    </collision>
  </link>
  <link name="Part4-1">
    <inertial>
      <origin xyz="0.05499979320860039 -3.4402451815074286e-07 -0.0014999875895955576" rpy="0 0 0"/>
      <mass value="0.00204302"/>
      <inertia ixx="8.60805e-09" ixy="0.0" ixz="0.0" iyy="2.22351e-06" iyz="0.0" izz="2.22905e-06"/>
    </inertial>
    <visual>
      <origin xyz="0.10999975708391281 -3.2470335274703555e-07 -0.003000058562568746" rpy="0 0 0"/>
      <geometry>
        <mesh filename="simple - part4-1.stl"/>
      </geometry>
      <material name="Part4-1_color">
        <color rgba="0.792157 0.819608 0.933333 1.0"/>
      </material>
    </visual>
    <collision>
      <origin xyz="0.10999975708391281 -3.2470335274703555e-07 -0.003000058562568746" rpy="0 0 0"/>
      <geometry>
        <mesh filename="simple - part4-1.stl"/>
      </geometry>
    </collision>
  </link>
  <joint name="Part4-1--Part4-2" type="continuous">
    <origin xyz="0.07660586036889852 -0.10958518755115226 0.02447965538543597" rpy="4.997148514186109e-07 1.4515370940064013e-07 1.6760561249726054"/>
    <axis xyz="-2.1777681014079064e-07 -5.940162189077558e-07 -0.9999998245782846"/>
    <parent link="Part4-2"/>
    <child link="Part4-1"/>
    <dynamics damping="0.1"/>
  </joint>
  <link name="Hexagon Nut ISO - 4032 - M5 - W - N-2">
    <inertial>
      <origin xyz="0 0 -0.002326470491660893" rpy="0 0 0"/>
      <mass value="0.00019053"/>
      <inertia ixx="1.39043e-09" ixy="-7.15756e-17" ixz="0.0" iyy="1.39043e-09" iyz="-3.52631e-16" izz="2.10777e-09"/>
    </inertial>
    <visual>
      <origin xyz="0 0 0" rpy="0 0 0"/>
      <geometry>
        <mesh filename="simple - hexagon nut iso - 4032 - m5 - w - n-2.stl"/>
      </geometry>
      <material name="Hexagon Nut ISO - 4032 - M5 - W - N-2_color">
        <color rgba="0.776471 0.756863 0.737255 1.0"/>
      </material>
    </visual>
    <collision>
      <origin xyz="0 0 0" rpy="0 0 0"/>
      <geometry>
        <mesh filename="simple - hexagon nut iso - 4032 - m5 - w - n-2.stl"/>
      </geometry>
    </collision>
  </link>
  <joint name="Part4-1--Hexagon Nut ISO - 4032 - M5 - W - N-2" type="fixed">
    <origin xyz="0 0 -0.0076999945924405115" rpy="3.1415919631475178 0 -0.3623347415095002"/>
    <parent link="Part4-1"/>
    <child link="Hexagon Nut ISO - 4032 - M5 - W - N-2"/>
    <dynamics damping="0.1"/>
  </joint>
  <link name="Part2-1">
    <inertial>
      <origin xyz="0 6.553303299453809e-05 0.0012129999999999988" rpy="0 0 0"/>
      <mass value="0.00107835"/>
      <inertia ixx="4.41673e-08" ixy="0.0" ixz="0.0" iyy="4.45945e-08" iyz="4.03831e-10" izz="7.79296e-08"/>
    </inertial>
    <visual>
      <origin xyz="0 0 0" rpy="0 0 0"/>
      <geometry>
        <mesh filename="simple - part2-1.stl"/>
      </geometry>
      <material name="Part2-1_color">
        <color rgba="0.792157 0.819608 0.933333 1.0"/>
      </material>
    </visual>
    <collision>
      <origin xyz="0 0 0" rpy="0 0 0"/>
      <geometry>
        <mesh filename="simple - part2-1.stl"/>
      </geometry>
    </collision>
  </link>
  <joint name="Part2-1--Part4-1" type="fixed">
    <origin xyz="0.11224978200316417 0.0038967737870765143 -0.005000010291646668" rpy="1.570796950116546 0 2.617993869704933"/>
    <parent link="Part4-1"/>
    <child link="Part2-1"/>
    <dynamics damping="0.1"/>
  </joint>
  <link name="Hexagon Nut ISO - 4032 - M5 - W - N-1">
    <inertial>
      <origin xyz="0 0 -0.0023265168156459534" rpy="0 0 0"/>
      <mass value="0.00019053"/>
      <inertia ixx="1.39043e-09" ixy="-7.15756e-17" ixz="0.0" iyy="1.39043e-09" iyz="-3.52631e-16" izz="2.10777e-09"/>
    </inertial>
    <visual>
      <origin xyz="0 0 0" rpy="0 0 0"/>
      <geometry>
        <mesh filename="simple - hexagon nut iso - 4032 - m5 - w - n-1.stl"/>
      </geometry>
      <material name="Hexagon Nut ISO - 4032 - M5 - W - N-1_color">
        <color rgba="0.776471 0.756863 0.737255 1.0"/>
      </material>
    </visual>
    <collision>
      <origin xyz="0 0 0" rpy="0 0 0"/>
      <geometry>
        <mesh filename="simple - hexagon nut iso - 4032 - m5 - w - n-1.stl"/>
      </geometry>
    </collision>
  </link>
  <joint name="Part2-1--Hexagon Nut ISO - 4032 - M5 - W - N-1" type="fixed">
    <origin xyz="0 -0.004700034434788623 -0.004499999999999997" rpy="-1.570796954524512 0.6898802923351496 3.141592529600631"/>
    <parent link="Part2-1"/>
    <child link="Hexagon Nut ISO - 4032 - M5 - W - N-1"/>
    <dynamics damping="0.1"/>
  </joint>
  <link name="part1-1">
    <inertial>
      <origin xyz="0 0 -0.009338100000000002" rpy="0 0 0"/>
      <mass value="0.0215356"/>
      <inertia ixx="3.39052e-06" ixy="0.0" ixz="0.0" iyy="3.39052e-06" iyz="0.0" izz="6.25091e-06"/>
    </inertial>
    <visual>
      <origin xyz="0 0 -0.015" rpy="0 0 0"/>
      <geometry>
        <mesh filename="simple - part1-1.stl"/>
      </geometry>
      <material name="part1-1_color">
        <color rgba="0.792157 0.819608 0.933333 1.0"/>
      </material>
    </visual>
    <collision>
      <origin xyz="0 0 -0.015" rpy="0 0 0"/>
      <geometry>
        <mesh filename="simple - part1-1.stl"/>
      </geometry>
    </collision>
  </link>
  <joint name="part1-1--Part2-1" type="continuous">
    <origin xyz="0 0 0.0020000000000000018" rpy="3.141592653589793 0 -2.755743458119967"/>
    <axis xyz="0.0 0.0 -1.0"/>
    <parent link="Part2-1"/>
    <child link="part1-1"/>
    <dynamics damping="0.1"/>
  </joint>
  <link name="ISO 7045 - M5 x 6 - Z --- 6S-2">
    <inertial>
      <origin xyz="9.75656169127535e-05 0 0" rpy="0 0 0"/>
      <mass value="0.000297704"/>
      <inertia ixx="2.41963e-09" ixy="7.00947e-20" ixz="-5.87906e-20" iyy="2.96347e-09" iyz="0.0" izz="2.96347e-09"/>
    </inertial>
    <visual>
      <origin xyz="-0.003699939818154409 0 0" rpy="0 0 0"/>
      <geometry>
        <mesh filename="simple - iso 7045 - m5 x 6 - z --- 6s-2.stl"/>
      </geometry>
      <material name="ISO 7045 - M5 x 6 - Z --- 6S-2_color">
        <color rgba="0.776471 0.756863 0.737255 1.0"/>
      </material>
    </visual>
    <collision>
      <origin xyz="-0.003699939818154409 0 0" rpy="0 0 0"/>
      <geometry>
        <mesh filename="simple - iso 7045 - m5 x 6 - z --- 6s-2.stl"/>
      </geometry>
    </collision>
  </link>
  <joint name="Part4-1--ISO 7045 - M5 x 6 - Z --- 6S-2" type="fixed">
    <origin xyz="0.10999980876001422 -3.523792835094519e-07 0" rpy="0.3485292877553672 1.5707956635992741 -1.745865823545737"/>
    <axis xyz="0.9999998245784778 -1.180839386827337e-07 0.0"/>
    <parent link="Part4-1"/>
    <child link="ISO 7045 - M5 x 6 - Z --- 6S-2"/>
    <dynamics damping="0.1"/>
  </joint>
  <link name="ISO 7045 - M5 x 8 - Z --- 8S-3">
    <inertial>
      <origin xyz="0.00081706187654048 0 0" rpy="0 0 0"/>
      <mass value="0.000332876"/>
      <inertia ixx="2.51955e-09" ixy="6.3864e-20" ixz="-6.50208e-20" iyy="4.49484e-09" iyz="0.0" izz="4.49484e-09"/>
    </inertial>
    <visual>
      <origin xyz="-0.0036999670370751296 0 0" rpy="0 0 0"/>
      <geometry>
        <mesh filename="simple - iso 7045 - m5 x 8 - z --- 8s-3.stl"/>
      </geometry>
      <material name="ISO 7045 - M5 x 8 - Z --- 8S-3_color">
        <color rgba="0.776471 0.756863 0.737255 1.0"/>
      </material>
    </visual>
    <collision>
      <origin xyz="-0.0036999670370751296 0 0" rpy="0 0 0"/>
      <geometry>
        <mesh filename="simple - iso 7045 - m5 x 8 - z --- 8s-3.stl"/>
      </geometry>
    </collision>
  </link>
  <joint name="Part4-2--ISO 7045 - M5 x 8 - Z --- 8S-3" type="continuous">
    <origin xyz="0.07660583709652072 -0.10958523795464671 0.027479680972079836" rpy="-0.5154449425783086 1.5707960243690036 -0.9337839281826141"/>
    <axis xyz="0.9999998245784778 -1.180839386827337e-07 0.0"/>
    <parent link="Part4-2"/>
    <child link="ISO 7045 - M5 x 8 - Z --- 8S-3"/>
    <dynamics damping="0.1"/>
  </joint>
  <gazebo reference="Part4-2">
    <visual>
      <material>
        <ambient>0.792157 0.819608 0.933333 1.0</ambient>
        <diffuse>0.792157 0.819608 0.933333 1.0</diffuse>
        <specular>0.3960785 0.409804 0.4666665 1.0</specular>
      </material>
    </visual>
  </gazebo>
  <gazebo reference="Part4-1">
    <visual>
      <material>
        <ambient>0.792157 0.819608 0.933333 1.0</ambient>
        <diffuse>0.792157 0.819608 0.933333 1.0</diffuse>
        <specular>0.3960785 0.409804 0.4666665 1.0</specular>
      </material>
    </visual>
  </gazebo>
  <gazebo reference="Hexagon Nut ISO - 4032 - M5 - W - N-2">
    <visual>
      <material>
        <ambient>0.776471 0.756863 0.737255 1.0</ambient>
        <diffuse>0.776471 0.756863 0.737255 1.0</diffuse>
        <specular>0.3882355 0.3784315 0.3686275 1.0</specular>
      </material>
    </visual>
  </gazebo>
  <gazebo reference="Part2-1">
    <visual>
      <material>
        <ambient>0.792157 0.819608 0.933333 1.0</ambient>
        <diffuse>0.792157 0.819608 0.933333 1.0</diffuse>
        <specular>0.3960785 0.409804 0.4666665 1.0</specular>
      </material>
    </visual>
  </gazebo>
  <gazebo reference="Hexagon Nut ISO - 4032 - M5 - W - N-1">
    <visual>
      <material>
        <ambient>0.776471 0.756863 0.737255 1.0</ambient>
        <diffuse>0.776471 0.756863 0.737255 1.0</diffuse>
        <specular>0.3882355 0.3784315 0.3686275 1.0</specular>
      </material>
    </visual>
  </gazebo>
  <gazebo reference="part1-1">
    <visual>
      <material>
        <ambient>0.792157 0.819608 0.933333 1.0</ambient>
        <diffuse>0.792157 0.819608 0.933333 1.0</diffuse>
        <specular>0.3960785 0.409804 0.4666665 1.0</specular>
      </material>
    </visual>
  </gazebo>
  <gazebo reference="ISO 7045 - M5 x 6 - Z --- 6S-2">
    <visual>
      <material>
        <ambient>0.776471 0.756863 0.737255 1.0</ambient>
        <diffuse>0.776471 0.756863 0.737255 1.0</diffuse>
        <specular>0.3882355 0.3784315 0.3686275 1.0</specular>
      </material>
    </visual>
  </gazebo>
  <gazebo reference="ISO 7045 - M5 x 8 - Z --- 8S-3">
    <visual>
      <material>
        <ambient>0.776471 0.756863 0.737255 1.0</ambient>
        <diffuse>0.776471 0.756863 0.737255 1.0</diffuse>
        <specular>0.3882355 0.3784315 0.3686275 1.0</specular>
      </material>
    </visual>
  </gazebo>
  <gazebo>
    <pose>0.0 0.0 0.0 0.0 0.0 0.0</pose>
  </gazebo>
</robot>
